Exception on /submit_qvg_survey [POST]
Traceback (most recent call last):
  File "/home/cesar/environnements/overcooked/lib/python3.11/site-packages/flask/app.py", line 1511, in wsgi_app
    response = self.full_dispatch_request()
               ^^^^^^^^^^^^^^^^^^^^^^^^^^^^
  File "/home/cesar/environnements/overcooked/lib/python3.11/site-packages/flask/app.py", line 919, in full_dispatch_request
    rv = self.handle_user_exception(e)
         ^^^^^^^^^^^^^^^^^^^^^^^^^^^^^
  File "/home/cesar/environnements/overcooked/lib/python3.11/site-packages/flask/app.py", line 917, in full_dispatch_request
    rv = self.dispatch_request()
         ^^^^^^^^^^^^^^^^^^^^^^^
  File "/home/cesar/environnements/overcooked/lib/python3.11/site-packages/flask/app.py", line 902, in dispatch_request
    return self.ensure_sync(self.view_functions[rule.endpoint])(**view_args)  # type: ignore[no-any-return]
           ^^^^^^^^^^^^^^^^^^^^^^^^^^^^^^^^^^^^^^^^^^^^^^^^^^^^^^^^^^^^^^^^^
  File "/home/cesar/environnements/overcooked/lib/python3.11/site-packages/flask_login/utils.py", line 290, in decorated_view
    return current_app.ensure_sync(func)(*args, **kwargs)
           ^^^^^^^^^^^^^^^^^^^^^^^^^^^^^^^^^^^^^^^^^^^^^^
  File "/home/cesar/python-projects/Overcooked-coop-voice-1/app.py", line 781, in submit_qvg_survey
    config_id = CONFIG[config_id]
                       ^^^^^^^^^
UnboundLocalError: cannot access local variable 'config_id' where it is not associated with a value
Exception on /submit_qvg_survey [POST]
Traceback (most recent call last):
  File "/home/cesar/environnements/overcooked/lib/python3.11/site-packages/flask/app.py", line 1511, in wsgi_app
    response = self.full_dispatch_request()
               ^^^^^^^^^^^^^^^^^^^^^^^^^^^^
  File "/home/cesar/environnements/overcooked/lib/python3.11/site-packages/flask/app.py", line 919, in full_dispatch_request
    rv = self.handle_user_exception(e)
         ^^^^^^^^^^^^^^^^^^^^^^^^^^^^^
  File "/home/cesar/environnements/overcooked/lib/python3.11/site-packages/flask/app.py", line 917, in full_dispatch_request
    rv = self.dispatch_request()
         ^^^^^^^^^^^^^^^^^^^^^^^
  File "/home/cesar/environnements/overcooked/lib/python3.11/site-packages/flask/app.py", line 902, in dispatch_request
    return self.ensure_sync(self.view_functions[rule.endpoint])(**view_args)  # type: ignore[no-any-return]
           ^^^^^^^^^^^^^^^^^^^^^^^^^^^^^^^^^^^^^^^^^^^^^^^^^^^^^^^^^^^^^^^^^
  File "/home/cesar/environnements/overcooked/lib/python3.11/site-packages/flask_login/utils.py", line 290, in decorated_view
    return current_app.ensure_sync(func)(*args, **kwargs)
           ^^^^^^^^^^^^^^^^^^^^^^^^^^^^^^^^^^^^^^^^^^^^^^
  File "/home/cesar/python-projects/Overcooked-coop-voice-1/app.py", line 781, in submit_qvg_survey
    config_id = config["config_id"]
                ^^^^^^
NameError: name 'config' is not defined
Exception on /submit_qvg_survey [POST]
Traceback (most recent call last):
  File "/home/cesar/environnements/overcooked/lib/python3.11/site-packages/flask/app.py", line 1511, in wsgi_app
    response = self.full_dispatch_request()
               ^^^^^^^^^^^^^^^^^^^^^^^^^^^^
  File "/home/cesar/environnements/overcooked/lib/python3.11/site-packages/flask/app.py", line 919, in full_dispatch_request
    rv = self.handle_user_exception(e)
         ^^^^^^^^^^^^^^^^^^^^^^^^^^^^^
  File "/home/cesar/environnements/overcooked/lib/python3.11/site-packages/flask/app.py", line 917, in full_dispatch_request
    rv = self.dispatch_request()
         ^^^^^^^^^^^^^^^^^^^^^^^
  File "/home/cesar/environnements/overcooked/lib/python3.11/site-packages/flask/app.py", line 902, in dispatch_request
    return self.ensure_sync(self.view_functions[rule.endpoint])(**view_args)  # type: ignore[no-any-return]
           ^^^^^^^^^^^^^^^^^^^^^^^^^^^^^^^^^^^^^^^^^^^^^^^^^^^^^^^^^^^^^^^^^
  File "/home/cesar/environnements/overcooked/lib/python3.11/site-packages/flask_login/utils.py", line 290, in decorated_view
    return current_app.ensure_sync(func)(*args, **kwargs)
           ^^^^^^^^^^^^^^^^^^^^^^^^^^^^^^^^^^^^^^^^^^^^^^
  File "/home/cesar/python-projects/Overcooked-coop-voice-1/app.py", line 782, in submit_qvg_survey
    file_name = f"trajectories/" + current_user.config["config_id"] + "/"+ uid +"/"+ {uid} + "_" + {step}+"_QVG.json"
                ~~~~~~~~~~~~~~~~~~~~~~~~~~~~~~~~~~~~~~~~~~~~~~~~~~~~~~~~~~~~~~~~~~~^~~~~~~
TypeError: can only concatenate str (not "set") to str
Exception on /submit_qvg_survey [POST]
Traceback (most recent call last):
  File "/home/cesar/environnements/overcooked/lib/python3.11/site-packages/flask/app.py", line 1511, in wsgi_app
    response = self.full_dispatch_request()
               ^^^^^^^^^^^^^^^^^^^^^^^^^^^^
  File "/home/cesar/environnements/overcooked/lib/python3.11/site-packages/flask/app.py", line 919, in full_dispatch_request
    rv = self.handle_user_exception(e)
         ^^^^^^^^^^^^^^^^^^^^^^^^^^^^^
  File "/home/cesar/environnements/overcooked/lib/python3.11/site-packages/flask/app.py", line 917, in full_dispatch_request
    rv = self.dispatch_request()
         ^^^^^^^^^^^^^^^^^^^^^^^
  File "/home/cesar/environnements/overcooked/lib/python3.11/site-packages/flask/app.py", line 902, in dispatch_request
    return self.ensure_sync(self.view_functions[rule.endpoint])(**view_args)  # type: ignore[no-any-return]
           ^^^^^^^^^^^^^^^^^^^^^^^^^^^^^^^^^^^^^^^^^^^^^^^^^^^^^^^^^^^^^^^^^
  File "/home/cesar/environnements/overcooked/lib/python3.11/site-packages/flask_login/utils.py", line 290, in decorated_view
    return current_app.ensure_sync(func)(*args, **kwargs)
           ^^^^^^^^^^^^^^^^^^^^^^^^^^^^^^^^^^^^^^^^^^^^^^
  File "/home/cesar/python-projects/Overcooked-coop-voice-1/app.py", line 781, in submit_qvg_survey
    config_name = current_user.config["config_name"]
                  ~~~~~~~~~~~~~~~~~~~^^^^^^^^^^^^^^^
KeyError: 'config_name'
Exception on /submit_qvg_survey [POST]
Traceback (most recent call last):
  File "/home/cesar/environnements/overcooked/lib/python3.11/site-packages/flask/app.py", line 1511, in wsgi_app
    response = self.full_dispatch_request()
               ^^^^^^^^^^^^^^^^^^^^^^^^^^^^
  File "/home/cesar/environnements/overcooked/lib/python3.11/site-packages/flask/app.py", line 919, in full_dispatch_request
    rv = self.handle_user_exception(e)
         ^^^^^^^^^^^^^^^^^^^^^^^^^^^^^
  File "/home/cesar/environnements/overcooked/lib/python3.11/site-packages/flask/app.py", line 917, in full_dispatch_request
    rv = self.dispatch_request()
         ^^^^^^^^^^^^^^^^^^^^^^^
  File "/home/cesar/environnements/overcooked/lib/python3.11/site-packages/flask/app.py", line 902, in dispatch_request
    return self.ensure_sync(self.view_functions[rule.endpoint])(**view_args)  # type: ignore[no-any-return]
           ^^^^^^^^^^^^^^^^^^^^^^^^^^^^^^^^^^^^^^^^^^^^^^^^^^^^^^^^^^^^^^^^^
  File "/home/cesar/environnements/overcooked/lib/python3.11/site-packages/flask_login/utils.py", line 290, in decorated_view
    return current_app.ensure_sync(func)(*args, **kwargs)
           ^^^^^^^^^^^^^^^^^^^^^^^^^^^^^^^^^^^^^^^^^^^^^^
  File "/home/cesar/python-projects/Overcooked-coop-voice-1/app.py", line 781, in submit_qvg_survey
    config_name = current_user.config["config_name"]
                  ~~~~~~~~~~~~~~~~~~~^^^^^^^^^^^^^^^
KeyError: 'config_name'
Exception on / [GET]
Traceback (most recent call last):
  File "/home/cesar/environnements/overcooked/lib/python3.11/site-packages/flask/app.py", line 1511, in wsgi_app
    response = self.full_dispatch_request()
               ^^^^^^^^^^^^^^^^^^^^^^^^^^^^
  File "/home/cesar/environnements/overcooked/lib/python3.11/site-packages/flask/app.py", line 919, in full_dispatch_request
    rv = self.handle_user_exception(e)
         ^^^^^^^^^^^^^^^^^^^^^^^^^^^^^
  File "/home/cesar/environnements/overcooked/lib/python3.11/site-packages/flask/app.py", line 917, in full_dispatch_request
    rv = self.dispatch_request()
         ^^^^^^^^^^^^^^^^^^^^^^^
  File "/home/cesar/environnements/overcooked/lib/python3.11/site-packages/flask/app.py", line 902, in dispatch_request
    return self.ensure_sync(self.view_functions[rule.endpoint])(**view_args)  # type: ignore[no-any-return]
           ^^^^^^^^^^^^^^^^^^^^^^^^^^^^^^^^^^^^^^^^^^^^^^^^^^^^^^^^^^^^^^^^^
  File "/home/cesar/python-projects/Overcooked-coop-voice-1/app.py", line 484, in index
    qpt = json.load(f)
          ^^^^^^^^^^^^
  File "/usr/lib/python3.11/json/__init__.py", line 293, in load
    return loads(fp.read(),
           ^^^^^^^^^^^^^^^^
  File "/usr/lib/python3.11/json/__init__.py", line 346, in loads
    return _default_decoder.decode(s)
           ^^^^^^^^^^^^^^^^^^^^^^^^^^
  File "/usr/lib/python3.11/json/decoder.py", line 337, in decode
    obj, end = self.raw_decode(s, idx=_w(s, 0).end())
               ^^^^^^^^^^^^^^^^^^^^^^^^^^^^^^^^^^^^^^
  File "/usr/lib/python3.11/json/decoder.py", line 353, in raw_decode
    obj, end = self.scan_once(s, idx)
               ^^^^^^^^^^^^^^^^^^^^^^
json.decoder.JSONDecodeError: Expecting ',' delimiter: line 24 column 61 (char 1355)
Exception on /planning [GET]
Traceback (most recent call last):
  File "/home/cesar/environnements/overcooked/lib/python3.11/site-packages/flask/app.py", line 1511, in wsgi_app
    response = self.full_dispatch_request()
               ^^^^^^^^^^^^^^^^^^^^^^^^^^^^
  File "/home/cesar/environnements/overcooked/lib/python3.11/site-packages/flask/app.py", line 919, in full_dispatch_request
    rv = self.handle_user_exception(e)
         ^^^^^^^^^^^^^^^^^^^^^^^^^^^^^
  File "/home/cesar/environnements/overcooked/lib/python3.11/site-packages/flask/app.py", line 917, in full_dispatch_request
    rv = self.dispatch_request()
         ^^^^^^^^^^^^^^^^^^^^^^^
  File "/home/cesar/environnements/overcooked/lib/python3.11/site-packages/flask/app.py", line 902, in dispatch_request
    return self.ensure_sync(self.view_functions[rule.endpoint])(**view_args)  # type: ignore[no-any-return]
           ^^^^^^^^^^^^^^^^^^^^^^^^^^^^^^^^^^^^^^^^^^^^^^^^^^^^^^^^^^^^^^^^^
  File "/home/cesar/environnements/overcooked/lib/python3.11/site-packages/flask_login/utils.py", line 290, in decorated_view
    return current_app.ensure_sync(func)(*args, **kwargs)
           ^^^^^^^^^^^^^^^^^^^^^^^^^^^^^^^^^^^^^^^^^^^^^^
  File "/home/cesar/python-projects/Overcooked-coop-voice/app.py", line 595, in planning
    qpt = questionnaire_to_surveyjs(current_user.config["qpt"], current_user.step, current_user.config.get("pagify_qpt", False))#{"elements" :[value for key,value in current_user.config["qpt"].items() if current_user.step in value["steps"]] }
                                    ~~~~~~~~~~~~~~~~~~~^^^^^^^
KeyError: 'qpt'
Exception on / [GET]
Traceback (most recent call last):
  File "/home/cesar/environnements/overcooked/lib/python3.11/site-packages/flask/app.py", line 1511, in wsgi_app
    response = self.full_dispatch_request()
               ^^^^^^^^^^^^^^^^^^^^^^^^^^^^
  File "/home/cesar/environnements/overcooked/lib/python3.11/site-packages/flask/app.py", line 919, in full_dispatch_request
    rv = self.handle_user_exception(e)
         ^^^^^^^^^^^^^^^^^^^^^^^^^^^^^
  File "/home/cesar/environnements/overcooked/lib/python3.11/site-packages/flask/app.py", line 917, in full_dispatch_request
    rv = self.dispatch_request()
         ^^^^^^^^^^^^^^^^^^^^^^^
  File "/home/cesar/environnements/overcooked/lib/python3.11/site-packages/flask/app.py", line 902, in dispatch_request
    return self.ensure_sync(self.view_functions[rule.endpoint])(**view_args)  # type: ignore[no-any-return]
           ^^^^^^^^^^^^^^^^^^^^^^^^^^^^^^^^^^^^^^^^^^^^^^^^^^^^^^^^^^^^^^^^^
  File "/home/cesar/python-projects/Overcooked-coop-voice/app.py", line 509, in index
    bloc_key = current_user.config["bloc_order"][current_user.step]
               ~~~~~~~~~~~~~~~~~~~^^^^^^^^^^^^^^
KeyError: 'bloc_order'
Exception on / [GET]
Traceback (most recent call last):
  File "/home/cesar/environnements/overcooked/lib/python3.11/site-packages/flask/app.py", line 1511, in wsgi_app
    response = self.full_dispatch_request()
               ^^^^^^^^^^^^^^^^^^^^^^^^^^^^
  File "/home/cesar/environnements/overcooked/lib/python3.11/site-packages/flask/app.py", line 919, in full_dispatch_request
    rv = self.handle_user_exception(e)
         ^^^^^^^^^^^^^^^^^^^^^^^^^^^^^
  File "/home/cesar/environnements/overcooked/lib/python3.11/site-packages/flask/app.py", line 917, in full_dispatch_request
    rv = self.dispatch_request()
         ^^^^^^^^^^^^^^^^^^^^^^^
  File "/home/cesar/environnements/overcooked/lib/python3.11/site-packages/flask/app.py", line 902, in dispatch_request
    return self.ensure_sync(self.view_functions[rule.endpoint])(**view_args)  # type: ignore[no-any-return]
           ^^^^^^^^^^^^^^^^^^^^^^^^^^^^^^^^^^^^^^^^^^^^^^^^^^^^^^^^^^^^^^^^^
  File "/home/cesar/python-projects/Overcooked-coop-voice/app.py", line 509, in index
    bloc_key = current_user.config["bloc_order"][current_user.step]
               ~~~~~~~~~~~~~~~~~~~^^^^^^^^^^^^^^
KeyError: 'bloc_order'
Exception on /planning [GET]
Traceback (most recent call last):
  File "/home/cesar/environnements/OvercookedEnv/lib/python3.12/site-packages/flask/app.py", line 1511, in wsgi_app
    response = self.full_dispatch_request()
               ^^^^^^^^^^^^^^^^^^^^^^^^^^^^
  File "/home/cesar/environnements/OvercookedEnv/lib/python3.12/site-packages/flask/app.py", line 919, in full_dispatch_request
    rv = self.handle_user_exception(e)
         ^^^^^^^^^^^^^^^^^^^^^^^^^^^^^
  File "/home/cesar/environnements/OvercookedEnv/lib/python3.12/site-packages/flask/app.py", line 917, in full_dispatch_request
    rv = self.dispatch_request()
         ^^^^^^^^^^^^^^^^^^^^^^^
  File "/home/cesar/environnements/OvercookedEnv/lib/python3.12/site-packages/flask/app.py", line 902, in dispatch_request
    return self.ensure_sync(self.view_functions[rule.endpoint])(**view_args)  # type: ignore[no-any-return]
           ^^^^^^^^^^^^^^^^^^^^^^^^^^^^^^^^^^^^^^^^^^^^^^^^^^^^^^^^^^^^^^^^^
  File "/home/cesar/environnements/OvercookedEnv/lib/python3.12/site-packages/flask_login/utils.py", line 290, in decorated_view
    return current_app.ensure_sync(func)(*args, **kwargs)
           ^^^^^^^^^^^^^^^^^^^^^^^^^^^^^^^^^^^^^^^^^^^^^^
  File "/home/cesar/projet_python/Overcooked-coop-voice/app.py", line 631, in planning
    qpt = questionnaire_to_surveyjs(current_user.config["qpt"], current_user.config["bloc_order"][current_user.step], current_user.config.get("pagify_qpt", False))#{"elements" :[value for key,value in current_user.config["qpt"].items() if current_user.step in value["steps"]] }
                                                                ~~~~~~~~~~~~~~~~~~~^^^^^^^^^^^^^^
KeyError: 'bloc_order'
Exception on /instructions [POST]
Traceback (most recent call last):
  File "/home/cesar/environnements/OvercookedEnv/lib/python3.12/site-packages/flask/app.py", line 1511, in wsgi_app
    response = self.full_dispatch_request()
               ^^^^^^^^^^^^^^^^^^^^^^^^^^^^
  File "/home/cesar/environnements/OvercookedEnv/lib/python3.12/site-packages/flask/app.py", line 919, in full_dispatch_request
    rv = self.handle_user_exception(e)
         ^^^^^^^^^^^^^^^^^^^^^^^^^^^^^
  File "/home/cesar/environnements/OvercookedEnv/lib/python3.12/site-packages/flask/app.py", line 917, in full_dispatch_request
    rv = self.dispatch_request()
         ^^^^^^^^^^^^^^^^^^^^^^^
  File "/home/cesar/environnements/OvercookedEnv/lib/python3.12/site-packages/flask/app.py", line 902, in dispatch_request
    return self.ensure_sync(self.view_functions[rule.endpoint])(**view_args)  # type: ignore[no-any-return]
           ^^^^^^^^^^^^^^^^^^^^^^^^^^^^^^^^^^^^^^^^^^^^^^^^^^^^^^^^^^^^^^^^^
  File "/home/cesar/environnements/OvercookedEnv/lib/python3.12/site-packages/flask_login/utils.py", line 290, in decorated_view
    return current_app.ensure_sync(func)(*args, **kwargs)
           ^^^^^^^^^^^^^^^^^^^^^^^^^^^^^^^^^^^^^^^^^^^^^^
  File "/home/cesar/projet_python/Overcooked-coop-voice/app.py", line 565, in instructions
    all_conditions = [item for sublist in [list(bloc.values()) for bloc in condition.values()] for item in sublist] #test wheter at least 1 intention is given at some point
                                                ^^^^^^^^^^^
AttributeError: 'str' object has no attribute 'values'
Exception on /instructions [POST]
Traceback (most recent call last):
  File "/home/cesar/environnements/OvercookedEnv/lib/python3.12/site-packages/flask/app.py", line 1511, in wsgi_app
    response = self.full_dispatch_request()
               ^^^^^^^^^^^^^^^^^^^^^^^^^^^^
  File "/home/cesar/environnements/OvercookedEnv/lib/python3.12/site-packages/flask/app.py", line 919, in full_dispatch_request
    rv = self.handle_user_exception(e)
         ^^^^^^^^^^^^^^^^^^^^^^^^^^^^^
  File "/home/cesar/environnements/OvercookedEnv/lib/python3.12/site-packages/flask/app.py", line 917, in full_dispatch_request
    rv = self.dispatch_request()
         ^^^^^^^^^^^^^^^^^^^^^^^
  File "/home/cesar/environnements/OvercookedEnv/lib/python3.12/site-packages/flask/app.py", line 902, in dispatch_request
    return self.ensure_sync(self.view_functions[rule.endpoint])(**view_args)  # type: ignore[no-any-return]
           ^^^^^^^^^^^^^^^^^^^^^^^^^^^^^^^^^^^^^^^^^^^^^^^^^^^^^^^^^^^^^^^^^
  File "/home/cesar/environnements/OvercookedEnv/lib/python3.12/site-packages/flask_login/utils.py", line 290, in decorated_view
    return current_app.ensure_sync(func)(*args, **kwargs)
           ^^^^^^^^^^^^^^^^^^^^^^^^^^^^^^^^^^^^^^^^^^^^^^
  File "/home/cesar/projet_python/Overcooked-coop-voice/app.py", line 567, in instructions
    all_conditions = [item for sublist in [list(bloc.values()) for bloc in condition.values()] for item in sublist] #test wheter at least 1 intention is given at some point
                                                ^^^^^^^^^^^
AttributeError: 'str' object has no attribute 'values'
